Workbook

Sheet Dashboard
A1: Shipment Delivery & Returns Dashboard
A3: Q3 2026 (Jul - Sep) | Delivery performance against SLA and returns analysis
A6: TOTAL SHIPMENTS | D6: DELIVERED | G6: ON-TIME DELIVERY | J6: AVG TAT (DAYS) | M6: RETURN RATE | P6: RTO RATE
A7: ='Summary Tables'!A5 -> 800 | D7: ='Summary Tables'!B5 -> 662 | G7: ='Summary Tables'!A8 -> 0.60669456 | J7: ='Summary Tables'!B8 -> 3.7154812 | M7: ='Summary Tables'!D8 -> 0.06875 | P7: ='Summary Tables'!E8 -> 0.065
A10: On-Time % by Courier | J10: Return / RTO Reasons
A30: Shipment Status | J30: Average TAT by City (Days)

Sheet Summary Tables
A1: Shipment Delivery & Returns Report | Q3 2026
A2: Simulated shipment data (800 shipments, 4 couriers). All numbers are live formulas on the Tracker sheet.
A4: Total Shipments | B4: Delivered | C4: In Transit | D4: Returned | E4: RTO
A5: =COUNTA(Tracker!$A$2:$A$801) -> 800 | B5: =COUNTIFS(Tracker!$F$2:$F$801,"Delivered") -> 662 | C5: =COUNTIFS(Tracker!$F$2:$F$801,"In Transit") -> 31 | D5: =COUNTIFS(Tracker!$F$2:$F$801,"Returned") -> 55 | E5: =COUNTIFS(Tracker!$F$2:$F$801,"RTO") -> 52
A7: On-Time Delivery % | B7: Avg TAT (Days) | C7: Delayed Shipments | D7: Return Rate | E7: RTO Rate
A8: =COUNTIFS(Tracker!$J$2:$J$801,"On Time")/(COUNTIFS(Tracker!$J$2:$J$801,"On Time")+COUNTIFS(Tracker!$J$2:$J$801,"Delayed")) -> 0.60669456 | B8: =AVERAGE(Tracker!$I$2:$I$801) -> 3.7154812 | C8: =COUNTIFS(Tracker!$J$2:$J$801,"Delayed") -> 282 | D8: =D5/A5 -> 0.06875 | E8: =E5/A5 -> 0.065
A11: Courier Performance | J11: Shipment Status
A12: Courier | B12: Shipments | C12: Avg TAT (Days) | D12: Delayed | E12: On-Time % | F12: Returned + RTO | G12: Return + RTO % | J12: Status | K12: Count
A13: Courier A | B13: =COUNTIFS(Tracker!$E$2:$E$801,A13) -> 209 | C13: =IFERROR(AVERAGEIFS(Tracker!$I$2:$I$801,Tracker!$E$2:$E$801,A13),0) -> 3.2336957 | D13: =COUNTIFS(Tracker!$E$2:$E$801,A13,Tracker!$J$2:$J$801,"Delayed") -> 47 | E13: =IFERROR(COUNTIFS(Tracker!$E$2:$E$801,A13,Tracker!$J$2:$J$801,"On Time")/(COUNTIFS(Tracker!$E$2:$E$801,A13,Tracker!$J$2:$J$801,"On Time")+D13),0) -> 0.74456522 | F13: =COUNTIFS(Tracker!$E$2:$E$801,A13,Tracker!$F$2:$F$801,"Returned")+COUNTIFS(Tracker!$E$2:$E$801,A13,Tracker!$F$2:$F$801,"RTO") -> 23 | G13: =IFERROR(F13/B13,0) -> 0.11004785 | J13: Delivered | K13: =COUNTIFS(Tracker!$F$2:$F$801,J13) -> 662
A14: Courier B | B14: =COUNTIFS(Tracker!$E$2:$E$801,A14) -> 216 | C14: =IFERROR(AVERAGEIFS(Tracker!$I$2:$I$801,Tracker!$E$2:$E$801,A14),0) -> 3.625641 | D14: =COUNTIFS(Tracker!$E$2:$E$801,A14,Tracker!$J$2:$J$801,"Delayed") -> 76 | E14: =IFERROR(COUNTIFS(Tracker!$E$2:$E$801,A14,Tracker!$J$2:$J$801,"On Time")/(COUNTIFS(Tracker!$E$2:$E$801,A14,Tracker!$J$2:$J$801,"On Time")+D14),0) -> 0.61025641 | F14: =COUNTIFS(Tracker!$E$2:$E$801,A14,Tracker!$F$2:$F$801,"Returned")+COUNTIFS(Tracker!$E$2:$E$801,A14,Tracker!$F$2:$F$801,"RTO") -> 30 | G14: =IFERROR(F14/B14,0) -> 0.13888889 | J14: In Transit | K14: =COUNTIFS(Tracker!$F$2:$F$801,J14) -> 31
A15: Courier C | B15: =COUNTIFS(Tracker!$E$2:$E$801,A15) -> 187 | C15: =IFERROR(AVERAGEIFS(Tracker!$I$2:$I$801,Tracker!$E$2:$E$801,A15),0) -> 4.2093023 | D15: =COUNTIFS(Tracker!$E$2:$E$801,A15,Tracker!$J$2:$J$801,"Delayed") -> 98 | E15: =IFERROR(COUNTIFS(Tracker!$E$2:$E$801,A15,Tracker!$J$2:$J$801,"On Time")/(COUNTIFS(Tracker!$E$2:$E$801,A15,Tracker!$J$2:$J$801,"On Time")+D15),0) -> 0.43023256 | F15: =COUNTIFS(Tracker!$E$2:$E$801,A15,Tracker!$F$2:$F$801,"Returned")+COUNTIFS(Tracker!$E$2:$E$801,A15,Tracker!$F$2:$F$801,"RTO") -> 23 | G15: =IFERROR(F15/B15,0) -> 0.12299465 | J15: Returned | K15: =COUNTIFS(Tracker!$F$2:$F$801,J15) -> 55
A16: Courier D | B16: =COUNTIFS(Tracker!$E$2:$E$801,A16) -> 188 | C16: =IFERROR(AVERAGEIFS(Tracker!$I$2:$I$801,Tracker!$E$2:$E$801,A16),0) -> 3.8433735 | D16: =COUNTIFS(Tracker!$E$2:$E$801,A16,Tracker!$J$2:$J$801,"Delayed") -> 61 | E16: =IFERROR(COUNTIFS(Tracker!$E$2:$E$801,A16,Tracker!$J$2:$J$801,"On Time")/(COUNTIFS(Tracker!$E$2:$E$801,A16,Tracker!$J$2:$J$801,"On Time")+D16),0) -> 0.63253012 | F16: =COUNTIFS(Tracker!$E$2:$E$801,A16,Tracker!$F$2:$F$801,"Returned")+COUNTIFS(Tracker!$E$2:$E$801,A16,Tracker!$F$2:$F$801,"RTO") -> 31 | G16: =IFERROR(F16/B16,0) -> 0.16489362 | J16: RTO | K16: =COUNTIFS(Tracker!$F$2:$F$801,J16) -> 52
A19: Return / RTO Reasons | E19: City-wise Delivery
A20: Reason | B20: Count | C20: Share | E20: City | F20: Shipments | G20: Avg TAT | H20: Delayed %
A21: Damaged / wrong item | B21: =COUNTIFS(Tracker!$G$2:$G$801,A21) -> 22 | C21: =IFERROR(B21/SUM($B$21:$B$25),0) -> 0.20560748 | E21: Delhi | F21: =COUNTIFS(Tracker!$D$2:$D$801,E21) -> 178 | G21: =IFERROR(AVERAGEIFS(Tracker!$I$2:$I$801,Tracker!$D$2:$D$801,E21),0) -> 3.1483871 | H21: =IFERROR(COUNTIFS(Tracker!$D$2:$D$801,E21,Tracker!$J$2:$J$801,"Delayed")/(COUNTIFS(Tracker!$D$2:$D$801,E21,Tracker!$J$2:$J$801,"Delayed")+COUNTIFS(Tracker!$D$2:$D$801,E21,Tracker!$J$2:$J$801,"On Time")),0) -> 0.38064516
A22: Customer not available | B22: =COUNTIFS(Tracker!$G$2:$G$801,A22) -> 13 | C22: =IFERROR(B22/SUM($B$21:$B$25),0) -> 0.12149533 | E22: Mumbai | F22: =COUNTIFS(Tracker!$D$2:$D$801,E22) -> 171 | G22: =IFERROR(AVERAGEIFS(Tracker!$I$2:$I$801,Tracker!$D$2:$D$801,E22),0) -> 3.1935484 | H22: =IFERROR(COUNTIFS(Tracker!$D$2:$D$801,E22,Tracker!$J$2:$J$801,"Delayed")/(COUNTIFS(Tracker!$D$2:$D$801,E22,Tracker!$J$2:$J$801,"Delayed")+COUNTIFS(Tracker!$D$2:$D$801,E22,Tracker!$J$2:$J$801,"On Time")),0) -> 0.40645161
A23: Address issue | B23: =COUNTIFS(Tracker!$G$2:$G$801,A23) -> 26 | C23: =IFERROR(B23/SUM($B$21:$B$25),0) -> 0.24299065 | E23: Bengaluru | F23: =COUNTIFS(Tracker!$D$2:$D$801,E23) -> 123 | G23: =IFERROR(AVERAGEIFS(Tracker!$I$2:$I$801,Tracker!$D$2:$D$801,E23),0) -> 3.3181818 | H23: =IFERROR(COUNTIFS(Tracker!$D$2:$D$801,E23,Tracker!$J$2:$J$801,"Delayed")/(COUNTIFS(Tracker!$D$2:$D$801,E23,Tracker!$J$2:$J$801,"Delayed")+COUNTIFS(Tracker!$D$2:$D$801,E23,Tracker!$J$2:$J$801,"On Time")),0) -> 0.43636364
A24: Refused at delivery | B24: =COUNTIFS(Tracker!$G$2:$G$801,A24) -> 27 | C24: =IFERROR(B24/SUM($B$21:$B$25),0) -> 0.25233645 | E24: Hyderabad | F24: =COUNTIFS(Tracker!$D$2:$D$801,E24) -> 115 | G24: =IFERROR(AVERAGEIFS(Tracker!$I$2:$I$801,Tracker!$D$2:$D$801,E24),0) -> 3.0660377 | H24: =IFERROR(COUNTIFS(Tracker!$D$2:$D$801,E24,Tracker!$J$2:$J$801,"Delayed")/(COUNTIFS(Tracker!$D$2:$D$801,E24,Tracker!$J$2:$J$801,"Delayed")+COUNTIFS(Tracker!$D$2:$D$801,E24,Tracker!$J$2:$J$801,"On Time")),0) -> 0.3490566
A25: Changed mind | B25: =COUNTIFS(Tracker!$G$2:$G$801,A25) -> 19 | C25: =IFERROR(B25/SUM($B$21:$B$25),0) -> 0.17757009 | E25: Kolkata | F25: =COUNTIFS(Tracker!$D$2:$D$801,E25) -> 49 | G25: =IFERROR(AVERAGEIFS(Tracker!$I$2:$I$801,Tracker!$D$2:$D$801,E25),0) -> 4.1395349 | H25: =IFERROR(COUNTIFS(Tracker!$D$2:$D$801,E25,Tracker!$J$2:$J$801,"Delayed")/(COUNTIFS(Tracker!$D$2:$D$801,E25,Tracker!$J$2:$J$801,"Delayed")+COUNTIFS(Tracker!$D$2:$D$801,E25,Tracker!$J$2:$J$801,"On Time")),0) -> 0.34883721
E26: Jaipur | F26: =COUNTIFS(Tracker!$D$2:$D$801,E26) -> 56 | G26: =IFERROR(AVERAGEIFS(Tracker!$I$2:$I$801,Tracker!$D$2:$D$801,E26),0) -> 5.2653061 | H26: =IFERROR(COUNTIFS(Tracker!$D$2:$D$801,E26,Tracker!$J$2:$J$801,"Delayed")/(COUNTIFS(Tracker!$D$2:$D$801,E26,Tracker!$J$2:$J$801,"Delayed")+COUNTIFS(Tracker!$D$2:$D$801,E26,Tracker!$J$2:$J$801,"On Time")),0) -> 0.46938776
E27: Lucknow | F27: =COUNTIFS(Tracker!$D$2:$D$801,E27) -> 44 | G27: =IFERROR(AVERAGEIFS(Tracker!$I$2:$I$801,Tracker!$D$2:$D$801,E27),0) -> 5.1052632 | H27: =IFERROR(COUNTIFS(Tracker!$D$2:$D$801,E27,Tracker!$J$2:$J$801,"Delayed")/(COUNTIFS(Tracker!$D$2:$D$801,E27,Tracker!$J$2:$J$801,"Delayed")+COUNTIFS(Tracker!$D$2:$D$801,E27,Tracker!$J$2:$J$801,"On Time")),0) -> 0.39473684
E28: Indore | F28: =COUNTIFS(Tracker!$D$2:$D$801,E28) -> 29 | G28: =IFERROR(AVERAGEIFS(Tracker!$I$2:$I$801,Tracker!$D$2:$D$801,E28),0) -> 5 | H28: =IFERROR(COUNTIFS(Tracker!$D$2:$D$801,E28,Tracker!$J$2:$J$801,"Delayed")/(COUNTIFS(Tracker!$D$2:$D$801,E28,Tracker!$J$2:$J$801,"Delayed")+COUNTIFS(Tracker!$D$2:$D$801,E28,Tracker!$J$2:$J$801,"On Time")),0) -> 0.30769231
E29: Patna | F29: =COUNTIFS(Tracker!$D$2:$D$801,E29) -> 19 | G29: =IFERROR(AVERAGEIFS(Tracker!$I$2:$I$801,Tracker!$D$2:$D$801,E29),0) -> 5.7894737 | H29: =IFERROR(COUNTIFS(Tracker!$D$2:$D$801,E29,Tracker!$J$2:$J$801,"Delayed")/(COUNTIFS(Tracker!$D$2:$D$801,E29,Tracker!$J$2:$J$801,"Delayed")+COUNTIFS(Tracker!$D$2:$D$801,E29,Tracker!$J$2:$J$801,"On Time")),0) -> 0.31578947
E30: Guwahati | F30: =COUNTIFS(Tracker!$D$2:$D$801,E30) -> 16 | G30: =IFERROR(AVERAGEIFS(Tracker!$I$2:$I$801,Tracker!$D$2:$D$801,E30),0) -> 7.5625 | H30: =IFERROR(COUNTIFS(Tracker!$D$2:$D$801,E30,Tracker!$J$2:$J$801,"Delayed")/(COUNTIFS(Tracker!$D$2:$D$801,E30,Tracker!$J$2:$J$801,"Delayed")+COUNTIFS(Tracker!$D$2:$D$801,E30,Tracker!$J$2:$J$801,"On Time")),0) -> 0.5

Sheet Tracker
A1: Order ID | B1: Ship Date | C1: Delivery Date | D1: City | E1: Courier | F1: Status | G1: Return / RTO Reason | H1: SLA (Days) | I1: TAT (Days) | J1: Delivery Flag | K1: Days Delayed
A2: SHP50001 | B2: 46204 | C2: 46209 | D2: Indore | E2: Courier C | F2: Delivered | H2: =IFERROR(VLOOKUP(D2,Settings!$A$5:$C$14,3,FALSE()),"") -> 5 | I2: =IF(C2="","",C2-B2) -> 5 | J2: =IF(I2="","",IF(I2>H2,"Delayed","On Time")) -> On Time | K2: =IF(J2="Delayed",I2-H2,"")
A3: SHP50002 | B3: 46204 | C3: 46207 | D3: Mumbai | E3: Courier D | F3: Delivered | H3: =IFERROR(VLOOKUP(D3,Settings!$A$5:$C$14,3,FALSE()),"") -> 3 | I3: =IF(C3="","",C3-B3) -> 3 | J3: =IF(I3="","",IF(I3>H3,"Delayed","On Time")) -> On Time | K3: =IF(J3="Delayed",I3-H3,"")
A4: SHP50003 | B4: 46204 | C4: 46208 | D4: Jaipur | E4: Courier D | F4: Delivered | H4: =IFERROR(VLOOKUP(D4,Settings!$A$5:$C$14,3,FALSE()),"") -> 5 | I4: =IF(C4="","",C4-B4) -> 4 | J4: =IF(I4="","",IF(I4>H4,"Delayed","On Time")) -> On Time | K4: =IF(J4="Delayed",I4-H4,"")
A5: SHP50004 | B5: 46204 | C5: 46209 | D5: Delhi | E5: Courier B | F5: Delivered | H5: =IFERROR(VLOOKUP(D5,Settings!$A$5:$C$14,3,FALSE()),"") -> 3 | I5: =IF(C5="","",C5-B5) -> 5 | J5: =IF(I5="","",IF(I5>H5,"Delayed","On Time")) -> Delayed | K5: =IF(J5="Delayed",I5-H5,"") -> 2
A6: SHP50005 | B6: 46204 | C6: 46208 | D6: Jaipur | E6: Courier B | F6: Delivered | H6: =IFERROR(VLOOKUP(D6,Settings!$A$5:$C$14,3,FALSE()),"") -> 5 | I6: =IF(C6="","",C6-B6) -> 4 | J6: =IF(I6="","",IF(I6>H6,"Delayed","On Time")) -> On Time | K6: =IF(J6="Delayed",I6-H6,"")
A7: SHP50006 | B7: 46205 | D7: Jaipur | E7: Courier A | F7: RTO | G7: Refused at delivery | H7: =IFERROR(VLOOKUP(D7,Settings!$A$5:$C$14,3,FALSE()),"") -> 5 | I7: =IF(C7="","",C7-B7) | J7: =IF(I7="","",IF(I7>H7,"Delayed","On Time")) | K7: =IF(J7="Delayed",I7-H7,"")
A8: SHP50007 | B8: 46205 | C8: 46210 | D8: Jaipur | E8: Courier C | F8: Delivered | H8: =IFERROR(VLOOKUP(D8,Settings!$A$5:$C$14,3,FALSE()),"") -> 5 | I8: =IF(C8="","",C8-B8) -> 5 | J8: =IF(I8="","",IF(I8>H8,"Delayed","On Time")) -> On Time | K8: =IF(J8="Delayed",I8-H8,"")
A9: SHP50008 | B9: 46205 | C9: 46207 | D9: Delhi | E9: Courier D | F9: Delivered | H9: =IFERROR(VLOOKUP(D9,Settings!$A$5:$C$14,3,FALSE()),"") -> 3 | I9: =IF(C9="","",C9-B9) -> 2 | J9: =IF(I9="","",IF(I9>H9,"Delayed","On Time")) -> On Time | K9: =IF(J9="Delayed",I9-H9,"")
A10: SHP50009 | B10: 46205 | C10: 46207 | D10: Hyderabad | E10: Courier B | F10: Delivered | H10: =IFERROR(VLOOKUP(D10,Settings!$A$5:$C$14,3,FALSE()),"") -> 3 | I10: =IF(C10="","",C10-B10) -> 2 | J10: =IF(I10="","",IF(I10>H10,"Delayed","On Time")) -> On Time | K10: =IF(J10="Delayed",I10-H10,"")
A11: SHP50010 | B11: 46205 | C11: 46211 | D11: Delhi | E11: Courier A | F11: Delivered | H11: =IFERROR(VLOOKUP(D11,Settings!$A$5:$C$14,3,FALSE()),"") -> 3 | I11: =IF(C11="","",C11-B11) -> 6 | J11: =IF(I11="","",IF(I11>H11,"Delayed","On Time")) -> Delayed | K11: =IF(J11="Delayed",I11-H11,"") -> 3
A12: SHP50011 | B12: 46205 | C12: 46208 | D12: Hyderabad | E12: Courier B | F12: Delivered | H12: =IFERROR(VLOOKUP(D12,Settings!$A$5:$C$14,3,FALSE()),"") -> 3 | I12: =IF(C12="","",C12-B12) -> 3 | J12: =IF(I12="","",IF(I12>H12,"Delayed","On Time")) -> On Time | K12: =IF(J12="Delayed",I12-H12,"")
A13: SHP50012 | B13: 46205 | C13: 46208 | D13: Bengaluru | E13: Courier D | F13: Delivered | H13: =IFERROR(VLOOKUP(D13,Settings!$A$5:$C$14,3,FALSE()),"") -> 3 | I13: =IF(C13="","",C13-B13) -> 3 | J13: =IF(I13="","",IF(I13>H13,"Delayed","On Time")) -> On Time | K13: =IF(J13="Delayed",I13-H13,"")
A14: SHP50013 | B14: 46205 | D14: Delhi | E14: Courier C | F14: RTO | G14: Address issue | H14: =IFERROR(VLOOKUP(D14,Settings!$A$5:$C$14,3,FALSE()),"") -> 3 | I14: =IF(C14="","",C14-B14) | J14: =IF(I14="","",IF(I14>H14,"Delayed","On Time")) | K14: =IF(J14="Delayed",I14-H14,"")
A15: SHP50014 | B15: 46205 | C15: 46206 | D15: Bengaluru | E15: Courier A | F15: Delivered | H15: =IFERROR(VLOOKUP(D15,Settings!$A$5:$C$14,3,FALSE()),"") -> 3 | I15: =IF(C15="","",C15-B15) -> 1 | J15: =IF(I15="","",IF(I15>H15,"Delayed","On Time")) -> On Time | K15: =IF(J15="Delayed",I15-H15,"")
A16: SHP50015 | B16: 46205 | D16: Delhi | E16: Courier C | F16: RTO | G16: Customer not available | H16: =IFERROR(VLOOKUP(D16,Settings!$A$5:$C$14,3,FALSE()),"") -> 3 | I16: =IF(C16="","",C16-B16) | J16: =IF(I16="","",IF(I16>H16,"Delayed","On Time")) | K16: =IF(J16="Delayed",I16-H16,"")
A17: SHP50016 | B17: 46206 | C17: 46214 | D17: Guwahati | E17: Courier A | F17: Delivered | H17: =IFERROR(VLOOKUP(D17,Settings!$A$5:$C$14,3,FALSE()),"") -> 7 | I17: =IF(C17="","",C17-B17) -> 8 | J17: =IF(I17="","",IF(I17>H17,"Delayed","On Time")) -> Delayed | K17: =IF(J17="Delayed",I17-H17,"") -> 1
A18: SHP50017 | B18: 46206 | C18: 46211 | D18: Hyderabad | E18: Courier C | F18: Delivered | H18: =IFERROR(VLOOKUP(D18,Settings!$A$5:$C$14,3,FALSE()),"") -> 3 | I18: =IF(C18="","",C18-B18) -> 5 | J18: =IF(I18="","",IF(I18>H18,"Delayed","On Time")) -> Delayed | K18: =IF(J18="Delayed",I18-H18,"") -> 2
A19: SHP50018 | B19: 46206 | C19: 46209 | D19: Delhi | E19: Courier A | F19: Delivered | H19: =IFERROR(VLOOKUP(D19,Settings!$A$5:$C$14,3,FALSE()),"") -> 3 | I19: =IF(C19="","",C19-B19) -> 3 | J19: =IF(I19="","",IF(I19>H19,"Delayed","On Time")) -> On Time | K19: =IF(J19="Delayed",I19-H19,"")
A20: SHP50019 | B20: 46206 | C20: 46209 | D20: Delhi | E20: Courier D | F20: Returned | G20: Damaged / wrong item | H20: =IFERROR(VLOOKUP(D20,Settings!$A$5:$C$14,3,FALSE()),"") -> 3 | I20: =IF(C20="","",C20-B20) -> 3 | J20: =IF(I20="","",IF(I20>H20,"Delayed","On Time")) -> On Time | K20: =IF(J20="Delayed",I20-H20,"")
A21: SHP50020 | B21: 46207 | C21: 46215 | D21: Guwahati | E21: Courier C | F21: Delivered | H21: =IFERROR(VLOOKUP(D21,Settings!$A$5:$C$14,3,FALSE()),"") -> 7 | I21: =IF(C21="","",C21-B21) -> 8 | J21: =IF(I21="","",IF(I21>H21,"Delayed","On Time")) -> Delayed | K21: =IF(J21="Delayed",I21-H21,"") -> 1
A22: SHP50021 | B22: 46207 | C22: 46210 | D22: Delhi | E22: Courier D | F22: Delivered | H22: =IFERROR(VLOOKUP(D22,Settings!$A$5:$C$14,3,FALSE()),"") -> 3 | I22: =IF(C22="","",C22-B22) -> 3 | J22: =IF(I22="","",IF(I22>H22,"Delayed","On Time")) -> On Time | K22: =IF(J22="Delayed",I22-H22,"")
A23: SHP50022 | B23: 46207 | C23: 46213 | D23: Jaipur | E23: Courier D | F23: Delivered | H23: =IFERROR(VLOOKUP(D23,Settings!$A$5:$C$14,3,FALSE()),"") -> 5 | I23: =IF(C23="","",C23-B23) -> 6 | J23: =IF(I23="","",IF(I23>H23,"Delayed","On Time")) -> Delayed | K23: =IF(J23="Delayed",I23-H23,"") -> 1
A24: SHP50023 | B24: 46207 | C24: 46211 | D24: Mumbai | E24: Courier A | F24: Delivered | H24: =IFERROR(VLOOKUP(D24,Settings!$A$5:$C$14,3,FALSE()),"") -> 3 | I24: =IF(C24="","",C24-B24) -> 4 | J24: =IF(I24="","",IF(I24>H24,"Delayed","On Time")) -> Delayed | K24: =IF(J24="Delayed",I24-H24,"") -> 1
A25: SHP50024 | B25: 46208 | C25: 46215 | D25: Patna | E25: Courier C | F25: Delivered | H25: =IFERROR(VLOOKUP(D25,Settings!$A$5:$C$14,3,FALSE()),"") -> 6 | I25: =IF(C25="","",C25-B25) -> 7 | J25: =IF(I25="","",IF(I25>H25,"Delayed","On Time")) -> Delayed | K25: =IF(J25="Delayed",I25-H25,"") -> 1
A26: SHP50025 | B26: 46208 | C26: 46211 | D26: Mumbai | E26: Courier B | F26: Delivered | H26: =IFERROR(VLOOKUP(D26,Settings!$A$5:$C$14,3,FALSE()),"") -> 3 | I26: =IF(C26="","",C26-B26) -> 3 | J26: =IF(I26="","",IF(I26>H26,"Delayed","On Time")) -> On Time | K26: =IF(J26="Delayed",I26-H26,"")
A27: SHP50026 | B27: 46208 | C27: 46213 | D27: Bengaluru | E27: Courier D | F27: Delivered | H27: =IFERROR(VLOOKUP(D27,Settings!$A$5:$C$14,3,FALSE()),"") -> 3 | I27: =IF(C27="","",C27-B27) -> 5 | J27: =IF(I27="","",IF(I27>H27,"Delayed","On Time")) -> Delayed | K27: =IF(J27="Delayed",I27-H27,"") -> 2
A28: SHP50027 | B28: 46208 | C28: 46217 | D28: Indore | E28: Courier C | F28: Delivered | H28: =IFERROR(VLOOKUP(D28,Settings!$A$5:$C$14,3,FALSE()),"") -> 5 | I28: =IF(C28="","",C28-B28) -> 9 | J28: =IF(I28="","",IF(I28>H28,"Delayed","On Time")) -> Delayed | K28: =IF(J28="Delayed",I28-H28,"") -> 4
A29: SHP50028 | B29: 46208 | C29: 46212 | D29: Mumbai | E29: Courier B | F29: Delivered | H29: =IFERROR(VLOOKUP(D29,Settings!$A$5:$C$14,3,FALSE()),"") -> 3 | I29: =IF(C29="","",C29-B29) -> 4 | J29: =IF(I29="","",IF(I29>H29,"Delayed","On Time")) -> Delayed | K29: =IF(J29="Delayed",I29-H29,"") -> 1
A30: SHP50029 | B30: 46208 | C30: 46212 | D30: Bengaluru | E30: Courier B | F30: Delivered | H30: =IFERROR(VLOOKUP(D30,Settings!$A$5:$C$14,3,FALSE()),"") -> 3 | I30: =IF(C30="","",C30-B30) -> 4 | J30: =IF(I30="","",IF(I30>H30,"Delayed","On Time")) -> Delayed | K30: =IF(J30="Delayed",I30-H30,"") -> 1
A31: SHP50030 | B31: 46209 | C31: 46212 | D31: Hyderabad | E31: Courier B | F31: Delivered | H31: =IFERROR(VLOOKUP(D31,Settings!$A$5:$C$14,3,FALSE()),"") -> 3 | I31: =IF(C31="","",C31-B31) -> 3 | J31: =IF(I31="","",IF(I31>H31,"Delayed","On Time")) -> On Time | K31: =IF(J31="Delayed",I31-H31,"")
A32: SHP50031 | B32: 46209 | C32: 46215 | D32: Patna | E32: Courier D | F32: Delivered | H32: =IFERROR(VLOOKUP(D32,Settings!$A$5:$C$14,3,FALSE()),"") -> 6 | I32: =IF(C32="","",C32-B32) -> 6 | J32: =IF(I32="","",IF(I32>H32,"Delayed","On Time")) -> On Time | K32: =IF(J32="Delayed",I32-H32,"")
A33: SHP50032 | B33: 46209 | C33: 46211 | D33: Mumbai | E33: Courier B | F33: Returned | G33: Refused at delivery | H33: =IFERROR(VLOOKUP(D33,Settings!$A$5:$C$14,3,FALSE()),"") -> 3 | I33: =IF(C33="","",C33-B33) -> 2 | J33: =IF(I33="","",IF(I33>H33,"Delayed","On Time")) -> On Time | K33: =IF(J33="Delayed",I33-H33,"")
A34: SHP50033 | B34: 46209 | C34: 46211 | D34: Delhi | E34: Courier C | F34: Delivered | H34: =IFERROR(VLOOKUP(D34,Settings!$A$5:$C$14,3,FALSE()),"") -> 3 | I34: =IF(C34="","",C34-B34) -> 2 | J34: =IF(I34="","",IF(I34>H34,"Delayed","On Time")) -> On Time | K34: =IF(J34="Delayed",I34-H34,"")
A35: SHP50034 | B35: 46209 | C35: 46213 | D35: Mumbai | E35: Courier C | F35: Delivered | H35: =IFERROR(VLOOKUP(D35,Settings!$A$5:$C$14,3,FALSE()),"") -> 3 | I35: =IF(C35="","",C35-B35) -> 4 | J35: =IF(I35="","",IF(I35>H35,"Delayed","On Time")) -> Delayed | K35: =IF(J35="Delayed",I35-H35,"") -> 1
A36: SHP50035 | B36: 46209 | C36: 46212 | D36: Hyderabad | E36: Courier D | F36: Delivered | H36: =IFERROR(VLOOKUP(D36,Settings!$A$5:$C$14,3,FALSE()),"") -> 3 | I36: =IF(C36="","",C36-B36) -> 3 | J36: =IF(I36="","",IF(I36>H36,"Delayed","On Time")) -> On Time | K36: =IF(J36="Delayed",I36-H36,"")
A37: SHP50036 | B37: 46210 | C37: 46214 | D37: Jaipur | E37: Courier A | F37: Delivered | H37: =IFERROR(VLOOKUP(D37,Settings!$A$5:$C$14,3,FALSE()),"") -> 5 | I37: =IF(C37="","",C37-B37) -> 4 | J37: =IF(I37="","",IF(I37>H37,"Delayed","On Time")) -> On Time | K37: =IF(J37="Delayed",I37-H37,"")
A38: SHP50037 | B38: 46210 | C38: 46214 | D38: Delhi | E38: Courier B | F38: Delivered | H38: =IFERROR(VLOOKUP(D38,Settings!$A$5:$C$14,3,FALSE()),"") -> 3 | I38: =IF(C38="","",C38-B38) -> 4 | J38: =IF(I38="","",IF(I38>H38,"Delayed","On Time")) -> Delayed | K38: =IF(J38="Delayed",I38-H38,"") -> 1
A39: SHP50038 | B39: 46210 | C39: 46218 | D39: Guwahati | E39: Courier D | F39: Delivered | H39: =IFERROR(VLOOKUP(D39,Settings!$A$5:$C$14,3,FALSE()),"") -> 7 | I39: =IF(C39="","",C39-B39) -> 8 | J39: =IF(I39="","",IF(I39>H39,"Delayed","On Time")) -> Delayed | K39: =IF(J39="Delayed",I39-H39,"") -> 1
A40: SHP50039 | B40: 46210 | C40: 46216 | D40: Hyderabad | E40: Courier C | F40: Delivered | H40: =IFERROR(VLOOKUP(D40,Settings!$A$5:$C$14,3,FALSE()),"") -> 3 | I40: =IF(C40="","",C40-B40) -> 6 | J40: =IF(I40="","",IF(I40>H40,"Delayed","On Time")) -> Delayed | K40: =IF(J40="Delayed",I40-H40,"") -> 3
...

Sheet Settings
A1: Settings - City SLA (delivery promise in days)
A2: Edit blue cells. SLA is looked up by the Tracker sheet.
A4: City | B4: Zone | C4: SLA (Days) | E4: Status List | G4: Return / RTO Reasons | I4: Couriers
A5: Delhi | B5: Metro | C5: 3 | E5: Delivered | G5: Damaged / wrong item | I5: Courier A
A6: Mumbai | B6: Metro | C6: 3 | E6: In Transit | G6: Customer not available | I6: Courier B
A7: Bengaluru | B7: Metro | C7: 3 | E7: Returned | G7: Address issue | I7: Courier C
A8: Hyderabad | B8: Metro | C8: 3 | E8: RTO | G8: Refused at delivery | I8: Courier D
A9: Kolkata | B9: Metro | C9: 4 | G9: Changed mind
A10: Jaipur | B10: Tier-2 | C10: 5
A11: Lucknow | B11: Tier-2 | C11: 5
A12: Indore | B12: Tier-2 | C12: 5
A13: Patna | B13: Tier-2 | C13: 6
A14: Guwahati | B14: Remote | C14: 7

Sheet About
A1: About this workbook
A3: Purpose: Track shipments, measure delivery performance against SLA and analyse returns / RTO - a common task for an MIS Analyst in E-commerce.
A4: Data: SIMULATED sample data (800 shipments, 01-Jul-2026 to 30-Sep-2026). Not real company data.
A6: How it works:
A7: Tracker - enter data in blue columns A-G (dropdowns for City, Courier, Status, Reason).
A8: SLA, TAT, Delivery Flag and Days Delayed are formulas (black) and update automatically.
A9: Settings - change SLA days per city; the Tracker and Summary update instantly.
A10: Dashboard - KPI cards and 4 charts; Summary Tables - courier scorecard, return reasons and city-wise tables.
A12: Definitions: TAT = Delivery Date - Ship Date. Delayed = TAT greater than SLA. RTO = Return To Origin.
A13: Formulas used: VLOOKUP, IF, IFERROR, COUNTIFS, AVERAGEIFS, AVERAGE. Also data validation and conditional formatting.
A14: Note: shipments with status In Transit or RTO have no delivery date, so they are excluded from TAT / on-time calculations.
